<?xml version="1.0"?>
<sdf version="1.6">
  <model name="tethys">
    <!-- Body -->
    <link name="base_link">
      <inertial>
        <mass>147.8671</mass>
        <inertia>
          <ixx>3.000000</ixx>
          <ixy>0</ixy>
          <ixz>0</ixz>
          <iyy>41.980233</iyy>
          <iyz>0</iyz>
          <izz>41.980233</izz>
        </inertia>
      </inertial>

      <collision name="main_body_buoyancy">
        <geometry>
          <box>
            <size>2 0.3 0.2464451666666667</size>
          </box>
        </geometry>
      </collision>

      <visual name="visual">
        <geometry>
          <mesh>
            <uri>meshes/tethys.dae</uri>
            <submesh>
              <name>Body</name>
              <center>false</center>
            </submesh>
          </mesh>
        </geometry>
        <material>
          <diffuse>1.0 1.0 1.0</diffuse>
          <specular>1.0 1.0 1.0</specular>
          <pbr>
            <metal>
              <albedo_map>materials/textures/Tethys_Albedo.png</albedo_map>
              <normal_map>materials/textures/Tethys_Normal.png</normal_map>
              <metalness_map>materials/textures/Tethys_Metalness.png</metalness_map>
              <roughness_map>materials/textures/Tethys_Roughness.png</roughness_map>
            </metal>
          </pbr>
          <script>
            <uri>materials/scripts/</uri>
            <uri>materials/textures/</uri>
            <name>tethys/Tethys_Diffuse</name>
          </script>
        </material>
      </visual>
      
    <sensor name="imu_sensor" type="imu">
        <always_on>1</always_on>
        <update_rate>1</update_rate>
        <visualize>true</visualize>
        <topic>imu</topic>
    </sensor>
    <sensor name="magnetometer" type="magnetometer">
        <always_on>1</always_on>
        <update_rate>50</update_rate>
        <magnetometer>
          <x>
            <noise type="gaussian">
              <mean>0.000000080</mean>
              <bias_mean>0.000000400</bias_mean>
            </noise>
          </x>
          <y>
            <noise type="gaussian">
              <mean>0.000000080</mean>
              <bias_mean>0.000000400</bias_mean>
            </noise>
          </y>
          <z>
            <noise type="gaussian">
              <mean>0.000000080</mean>
              <bias_mean>0.000000400</bias_mean>
            </noise>
          </z>
        </magnetometer>
      </sensor>
      <sensor name="air_pressure" type="air_pressure">
        <always_on>1</always_on>
        <update_rate>20</update_rate>
        <air_pressure>
          <reference_altitude>0</reference_altitude>
          <noise type="gaussian">
            <mean>0.00000008</mean>
          </noise>
        </air_pressure>
      </sensor>
    

      
      <sensor name="ultrasonic_sensor_front" type="gpu_lidar">
        <pose relative_to='base_link'>-0.95 0 0  0 0 3.14</pose>
        <topic>close_one_to_sonar_front</topic>
              <update_rate>10</update_rate>
              <ray>
                <scan>
                  <horizontal>
                    <samples>150</samples>  <!-- Single beam -->
                    <resolution>1</resolution>
                    <min_angle>-0.60</min_angle>
                    <max_angle>0.60</max_angle>
                  </horizontal>
                  <vertical>
                    <samples>50</samples>  <!-- Single beam -->
                    <resolution>1</resolution>
                    <min_angle>-0.17</min_angle>
                    <max_angle>0.17</max_angle>
                  </vertical>
                </scan>
                <range>
                  <min>0.02</min>   <!-- Minimum range (e.g., 2 cm) -->
                  <max>10.0</max>    <!-- Maximum range (e.g., 4 m) -->
                  <resolution>0.01</resolution>
                </range>
              </ray>
              <visualize>true</visualize>
        </sensor>


        <sensor name="ultrasonic_sensor_top" type="gpu_lidar">
        <pose relative_to='base_link'>0 0 0.3 0 1.57    0</pose>
        <topic>close_one_to_sonar_top</topic>
              <update_rate>10</update_rate>
              <ray>
                <scan>
                  <vertical>
                  <samples>1</samples>  <!-- Single beam -->
                    <resolution>1.0</resolution>
                    <min_angle>0</min_angle>
                    <max_angle>0</max_angle>
                  </vertical>
                </scan>
                <range>
                  <min>0.02</min>   <!-- Minimum range (e.g., 2 cm) -->
                  <max>4.0</max>    <!-- Maximum range (e.g., 4 m) -->
                  <resolution>0.01</resolution>
                </range>
              </ray>
              <visualize>true</visualize>
        </sensor>


        <sensor name="ultrasonic_sensor_bottom" type="gpu_lidar">
        <pose relative_to='base_link'>0 0 -0.3  0 -1.57    0</pose>
        <topic>close_one_to_sonar_bottom</topic>
              <update_rate>10</update_rate>
              <ray>
                <scan>
                   <vertical>
                  <samples>1</samples>  <!-- Single beam -->
                    <resolution>1.0</resolution>
                    <min_angle>0</min_angle>
                    <max_angle>0</max_angle>
                  </vertical>
                </scan>
                <range>
                  <min>0.02</min>   <!-- Minimum range (e.g., 2 cm) -->
                  <max>4.0</max>    <!-- Maximum range (e.g., 4 m) -->
                  <resolution>0.01</resolution>
                </range>
              </ray>
              <visualize>true</visualize>
        </sensor>


    </link>

    <!-- Horizontal fins -->
    <link name="horizontal_fins">
      <pose>1.05 0 0 0 0 0</pose>
      <inertial>
        <pose>0 0 0 1.57 0 0.5</pose>
        <mass>0.2</mass>
        <inertia>
          <ixx>0.0007924568755</ixx>
          <ixy>-0.0000000002674</ixy>
          <ixz>0.0003978158176</ixz>
          <iyy>0.0010546736475</iyy>
          <iyz>-0.0000000006729</iyz>
          <izz>0.0002633558262</izz>
        </inertia>
      </inertial>

      <collision name="collision">
        <geometry>
          <box>
            <size>0.1 0.1 0.02</size>
          </box>
        </geometry>
      </collision> 

      <visual name= "visual">
        <pose>-1.05 0 0 0 0 0</pose>
        <geometry>
          <mesh>
            <uri>meshes/tethys.dae</uri>
            <submesh>
              <name>Fins_Horizontal</name>
              <center>false</center>
            </submesh>
          </mesh>
        </geometry>
        <material>
          <diffuse>1.0 1.0 1.0</diffuse>
          <specular>1.0 1.0 1.0</specular>
          <pbr>
            <metal>
              <albedo_map>materials/textures/Tethys_Albedo.png</albedo_map>
              <normal_map>materials/textures/Tethys_Normal.png</normal_map>
              <metalness_map>materials/textures/Tethys_Metalness.png</metalness_map>
              <roughness_map>materials/textures/Tethys_Roughness.png</roughness_map>
            </metal>
          </pbr>
          <script>
            <uri>materials/scripts/</uri>
            <uri>materials/textures/</uri>
            <name>tethys/Tethys_Diffuse</name>
          </script>
        </material>
      </visual>
    </link>

    <!-- Vertical fins -->
    <link name="vertical_fins">
      <pose>1.05 0 0 0 0 0</pose>
      <inertial>
        <mass>0.2</mass>
        <inertia>
          <ixx>0.0007924568755</ixx>
          <ixy>-0.0000000002674</ixy>
          <ixz>0.0003978158176</ixz>
          <iyy>0.0010546736475</iyy>
          <iyz>-0.0000000006729</iyz>
          <izz>0.0002633558262</izz>
        </inertia>
      </inertial>

      <collision name="collision">
         <geometry>
          <box>
            <size>0.1 0.1 0.02</size>
          </box>
        </geometry>
      </collision>

      <visual name= "visual">
        <pose>-1.05 0 0 0 0 0</pose>
        <geometry>
          <mesh>
            <uri>meshes/tethys.dae</uri>
            <submesh>
              <name>Fins_vertical</name>
              <center>false</center>
            </submesh>
          </mesh>
        </geometry>
        <material>
          <diffuse>1.0 1.0 1.0</diffuse>
          <specular>1.0 1.0 1.0</specular>
          <pbr>
            <metal>
              <albedo_map>materials/textures/Tethys_Albedo.png</albedo_map>
              <normal_map>materials/textures/Tethys_Normal.png</normal_map>
              <metalness_map>materials/textures/Tethys_Metalness.png</metalness_map>
              <roughness_map>materials/textures/Tethys_Roughness.png</roughness_map>
            </metal>
          </pbr>
          <script>
            <uri>materials/scripts/</uri>
            <uri>materials/textures/</uri>
            <name>tethys/Tethys_Diffuse</name>
          </script>
        </material>
      </visual>
    </link>

    <!-- Propeller -->
    <link name="propeller">
      <pose>1.43162 0 0 0 0 0</pose>
      <inertial>
        <pose>0 0 0 0 0 0</pose>
        <mass>0.09</mass>
        <inertia>
          <ixx>0.000143971303</ixx>
          <ixy>0.000000000008</ixy>
          <ixz>-0.000000000224</ixz>
          <iyy>0.000140915448</iyy>
          <iyz>-0.000025236433</iyz>
          <izz>0.000033571862</izz>
        </inertia>
      </inertial>

      <collision name="collision">
        <geometry>
          <box>
            <size>0.03 0.1 0.03</size>
          </box>
        </geometry>
      </collision>

      <visual name= "visual">
        <pose>-1.43162 0 0 0 0 0</pose>
        <geometry>
          <mesh>
            <uri>meshes/tethys.dae</uri>
            <submesh>
              <name>Prop</name>
              <center>false</center>
            </submesh>
          </mesh>
        </geometry>
        <material>
          <diffuse>1.0 1.0 1.0</diffuse>
          <specular>1.0 1.0 1.0</specular>
          <pbr>
            <metal>
              <albedo_map>materials/textures/Tethys_Albedo.png</albedo_map>
              <normal_map>materials/textures/Tethys_Normal.png</normal_map>
              <metalness_map>materials/textures/Tethys_Metalness.png</metalness_map>
              <roughness_map>materials/textures/Tethys_Roughness.png</roughness_map>
            </metal>
          </pbr>
          <script>
            <uri>materials/scripts/</uri>
            <uri>materials/textures/</uri>
            <name>tethys/Tethys_Diffuse</name>
          </script>
        </material>
      </visual>

    </link>

    <!-- Joints -->
    <joint name="horizontal_fins_joint" type="revolute">
      <pose>0 0 0 0 0 0</pose>
      <parent>base_link</parent>
      <child>horizontal_fins</child>
      <axis>
        <xyz>0 1 0</xyz>
        <limit>
          <lower>-0.261799</lower>
          <upper>0.261799</upper>
          <effort>-1</effort>
          <velocity>-1</velocity>
        </limit>
      </axis>
    </joint>

    <joint name="vertical_fins_joint" type="revolute">
      <pose>0 0 0 0 0 0</pose>
      <parent>base_link</parent>
      <child>vertical_fins</child>
      <axis>
        <xyz>0 0 1</xyz>
        <limit>
          <lower>-0.261799</lower>
          <upper>0.261799</upper>
          <effort>-1</effort>
          <velocity>-1</velocity>
        </limit>
      </axis>
    </joint>

    <joint name="propeller_joint" type="revolute">
      <pose>0 0 0 0 0 0</pose>
      <parent>base_link</parent>
      <child>propeller</child>
      <axis>
        <xyz>1 0 0</xyz>
        <limit>
          <lower>-1e+12</lower>
          <upper>1e+12</upper>
          <effort>-1</effort>
          <velocity>-1</velocity>
        </limit>
      </axis>
    </joint>
    <plugin
        filename="ignition-gazebo-pose-publisher-system"
        name="gz::sim::systems::PosePublisher">
        <publish_link_pose>true</publish_link_pose>
        <publish_collision_pose>false</publish_collision_pose>
        <publish_visual_pose>false</publish_visual_pose>
        <publish_nested_model_pose>false</publish_nested_model_pose>
      </plugin>


    <plugin
          filename="gz-sim-odometry-publisher-system"
          name="gz::sim::systems::OdometryPublisher">
        </plugin>
       
        
        <!-- Joint controllers -->
        <plugin
          filename="gz-sim-joint-position-controller-system"
          name="gz::sim::systems::JointPositionController">
          <joint_name>horizontal_fins_joint</joint_name>
          <p_gain>0.8</p_gain>
          <topic>
            /model/my_lrauv_modified/joint/horizontal_fins_cmd
           </topic>
        </plugin>
      
        <plugin
          filename="gz-sim-joint-position-controller-system"
          name="gz::sim::systems::JointPositionController">
          <joint_name>vertical_fins_joint</joint_name>
          <p_gain>0.8</p_gain>
          <topic>/model/my_lrauv_modified/joint/vertical_fins_cmd</topic>
    
        </plugin>
      
        <!-- Uncomment to add a thruster 
         <plugin
          filename="gz-sim-thruster-system"
          name="gz::sim::systems::Thruster">
          <namespace>my_lrauv</namespace>
          <use_angvel_cmd>1</use_angvel_cmd>
          <joint_name>propeller_joint</joint_name>
          <max_thrust_cmd>800N</max_thrust_cmd>
          <thrust_coefficient>0.004422</thrust_coefficient>
          <fluid_density>1000</fluid_density>
          <propeller_diameter>0.2</propeller_diameter>
        </plugin> -->
        <plugin
        filename="gz-sim-thruster-system"
        name="gz::sim::systems::Thruster">
        <namespace>my_lrauv</namespace>
        <use_angvel_cmd>0</use_angvel_cmd>
        <joint_name>propeller_joint</joint_name>
        <thrust_coefficient>0.004422</thrust_coefficient>
        <fluid_density>1000</fluid_density>
        <propeller_diameter>0.2</propeller_diameter>
      </plugin> 
        <!-- Lift and drag -->

        <!-- Vertical fin -->
        <plugin
          filename="gz-sim-lift-drag-system"
          name="gz::sim::systems::LiftDrag">
          <air_density>1000</air_density>
          <cla>4.13</cla>
          <cla_stall>-1.1</cla_stall>
          <cda>0.2</cda>
          <cda_stall>0.03</cda_stall>
          <alpha_stall>0.17</alpha_stall>
          <a0>0</a0>
          <area>0.0244</area>
          <upward>0 1 0</upward>
          <forward>-1 0 0</forward>
          <link_name>vertical_fins</link_name>
          <cp>0 0 0</cp>
        </plugin>

        <!-- Horizontal fin -->
        <plugin
          filename="gz-sim-lift-drag-system"
          name="gz::sim::systems::LiftDrag">
          <air_density>1000</air_density>
          <cla>4.13</cla>
          <cla_stall>-1.1</cla_stall>
          <cda>0.2</cda>
          <cda_stall>0.03</cda_stall>
          <alpha_stall>0.17</alpha_stall>
          <a0>0</a0>
          <area>0.0244</area>
          <upward>0 0 1</upward>
          <forward>1 0 0</forward>
          <link_name>horizontal_fins</link_name>
          <cp>0 0 0</cp>
        </plugin>

        <!-- Uncomment to add hydrodynamics -->
        <plugin
          filename="gz-sim-hydrodynamics-system"
          name="gz::sim::systems::Hydrodynamics">
          <link_name>base_link</link_name>
          <xDotU>-4.876161</xDotU>
          <yDotV>-126.324739</yDotV>
          <zDotW>-126.324739</zDotW>
          <kDotP>0</kDotP>
          <mDotQ>-33.46</mDotQ>
          <nDotR>-33.46</nDotR>
          <xUabsU>-6.2282</xUabsU>
          <xU>0</xU>
          <yVabsV>-601.27</yVabsV>
          <yV>0</yV>
          <zWabsW>-601.27</zWabsW>
          <zW>0</zW>
          <kPabsP>-0.1916</kPabsP>
          <kP>0</kP>
          <mQabsQ>-632.698957</mQabsQ>
          <mQ>0</mQ>
          <nRabsR>-632.698957</nRabsR>
          <nR>0</nR>
        </plugin>
  </model>
</sdf>
